{
 "cells": [
  {
   "cell_type": "code",
   "execution_count": 1,
   "metadata": {},
   "outputs": [
    {
     "name": "stdout",
     "output_type": "stream",
     "text": [
      "Requirement already up-to-date: pandas in c:\\users\\user\\anaconda3\\lib\\site-packages (0.25.1)\n",
      "Requirement already satisfied, skipping upgrade: pytz>=2017.2 in c:\\users\\user\\anaconda3\\lib\\site-packages (from pandas) (2019.3)\n",
      "Requirement already satisfied, skipping upgrade: numpy>=1.13.3 in c:\\users\\user\\anaconda3\\lib\\site-packages (from pandas) (1.18.2)\n",
      "Requirement already satisfied, skipping upgrade: python-dateutil>=2.6.1 in c:\\users\\user\\anaconda3\\lib\\site-packages (from pandas) (2.8.0)\n",
      "Requirement already satisfied, skipping upgrade: six>=1.5 in c:\\users\\user\\anaconda3\\lib\\site-packages (from python-dateutil>=2.6.1->pandas) (1.12.0)\n"
     ]
    },
    {
     "name": "stderr",
     "output_type": "stream",
     "text": [
      "WARNING: Retrying (Retry(total=4, connect=None, read=None, redirect=None, status=None)) after connection broken by 'NewConnectionError('<pip._vendor.urllib3.connection.VerifiedHTTPSConnection object at 0x0000013BF5D6AA08>: Failed to establish a new connection: [Errno 11001] getaddrinfo failed')': /simple/pandas/\n",
      "WARNING: Retrying (Retry(total=3, connect=None, read=None, redirect=None, status=None)) after connection broken by 'NewConnectionError('<pip._vendor.urllib3.connection.VerifiedHTTPSConnection object at 0x0000013BF5D6A9C8>: Failed to establish a new connection: [Errno 11001] getaddrinfo failed')': /simple/pandas/\n",
      "WARNING: Retrying (Retry(total=2, connect=None, read=None, redirect=None, status=None)) after connection broken by 'NewConnectionError('<pip._vendor.urllib3.connection.VerifiedHTTPSConnection object at 0x0000013BF5D6A2C8>: Failed to establish a new connection: [Errno 11001] getaddrinfo failed')': /simple/pandas/\n",
      "WARNING: Retrying (Retry(total=1, connect=None, read=None, redirect=None, status=None)) after connection broken by 'NewConnectionError('<pip._vendor.urllib3.connection.VerifiedHTTPSConnection object at 0x0000013BF5D69288>: Failed to establish a new connection: [Errno 11001] getaddrinfo failed')': /simple/pandas/\n",
      "WARNING: Retrying (Retry(total=0, connect=None, read=None, redirect=None, status=None)) after connection broken by 'NewConnectionError('<pip._vendor.urllib3.connection.VerifiedHTTPSConnection object at 0x0000013BF5D69EC8>: Failed to establish a new connection: [Errno 11001] getaddrinfo failed')': /simple/pandas/\n"
     ]
    }
   ],
   "source": [
    "!pip install pandas --upgrade"
   ]
  },
  {
   "cell_type": "code",
   "execution_count": 3,
   "metadata": {},
   "outputs": [],
   "source": [
    "import pandas as pd\n",
    "import numpy as np"
   ]
  },
  {
   "cell_type": "code",
   "execution_count": 4,
   "metadata": {},
   "outputs": [
    {
     "ename": "AttributeError",
     "evalue": "module 'pandas' has no attribute 'series'",
     "output_type": "error",
     "traceback": [
      "\u001b[1;31m---------------------------------------------------------------------------\u001b[0m",
      "\u001b[1;31mAttributeError\u001b[0m                            Traceback (most recent call last)",
      "\u001b[1;32m<ipython-input-4-406ceb394b8f>\u001b[0m in \u001b[0;36m<module>\u001b[1;34m\u001b[0m\n\u001b[1;32m----> 1\u001b[1;33m \u001b[0ma\u001b[0m\u001b[1;33m=\u001b[0m\u001b[0mpd\u001b[0m\u001b[1;33m.\u001b[0m\u001b[0mseries\u001b[0m\u001b[1;33m(\u001b[0m\u001b[1;33m)\u001b[0m\u001b[1;33m\u001b[0m\u001b[1;33m\u001b[0m\u001b[0m\n\u001b[0m\u001b[0;32m      2\u001b[0m \u001b[0mprint\u001b[0m\u001b[1;33m(\u001b[0m\u001b[0ma\u001b[0m\u001b[1;33m)\u001b[0m\u001b[1;33m\u001b[0m\u001b[1;33m\u001b[0m\u001b[0m\n",
      "\u001b[1;32m~\\Anaconda3\\lib\\site-packages\\pandas\\__init__.py\u001b[0m in \u001b[0;36m__getattr__\u001b[1;34m(name)\u001b[0m\n\u001b[0;32m    212\u001b[0m \u001b[1;33m\u001b[0m\u001b[0m\n\u001b[0;32m    213\u001b[0m             \u001b[1;32mreturn\u001b[0m \u001b[0mPanel\u001b[0m\u001b[1;33m\u001b[0m\u001b[1;33m\u001b[0m\u001b[0m\n\u001b[1;32m--> 214\u001b[1;33m         \u001b[1;32mraise\u001b[0m \u001b[0mAttributeError\u001b[0m\u001b[1;33m(\u001b[0m\u001b[1;34m\"module 'pandas' has no attribute '{}'\"\u001b[0m\u001b[1;33m.\u001b[0m\u001b[0mformat\u001b[0m\u001b[1;33m(\u001b[0m\u001b[0mname\u001b[0m\u001b[1;33m)\u001b[0m\u001b[1;33m)\u001b[0m\u001b[1;33m\u001b[0m\u001b[1;33m\u001b[0m\u001b[0m\n\u001b[0m\u001b[0;32m    215\u001b[0m \u001b[1;33m\u001b[0m\u001b[0m\n\u001b[0;32m    216\u001b[0m \u001b[1;33m\u001b[0m\u001b[0m\n",
      "\u001b[1;31mAttributeError\u001b[0m: module 'pandas' has no attribute 'series'"
     ]
    }
   ],
   "source": [
    "a=pd.series()\n",
    "print(a)"
   ]
  },
  {
   "cell_type": "code",
   "execution_count": 5,
   "metadata": {},
   "outputs": [
    {
     "name": "stdout",
     "output_type": "stream",
     "text": [
      "Requirement already satisfied: pandas in c:\\users\\user\\anaconda3\\lib\\site-packages (0.25.1)\n",
      "Requirement already satisfied: pytz>=2017.2 in c:\\users\\user\\anaconda3\\lib\\site-packages (from pandas) (2019.3)\n",
      "Requirement already satisfied: python-dateutil>=2.6.1 in c:\\users\\user\\anaconda3\\lib\\site-packages (from pandas) (2.8.0)\n",
      "Requirement already satisfied: numpy>=1.13.3 in c:\\users\\user\\anaconda3\\lib\\site-packages (from pandas) (1.18.2)\n",
      "Requirement already satisfied: six>=1.5 in c:\\users\\user\\anaconda3\\lib\\site-packages (from python-dateutil>=2.6.1->pandas) (1.12.0)\n"
     ]
    }
   ],
   "source": [
    "!pip install pandas"
   ]
  },
  {
   "cell_type": "code",
   "execution_count": 6,
   "metadata": {},
   "outputs": [
    {
     "name": "stdout",
     "output_type": "stream",
     "text": [
      "Requirement already up-to-date: pandas in c:\\users\\user\\anaconda3\\lib\\site-packages (0.25.1)\n",
      "Requirement already satisfied, skipping upgrade: numpy>=1.13.3 in c:\\users\\user\\anaconda3\\lib\\site-packages (from pandas) (1.18.2)\n",
      "Requirement already satisfied, skipping upgrade: python-dateutil>=2.6.1 in c:\\users\\user\\anaconda3\\lib\\site-packages (from pandas) (2.8.0)\n",
      "Requirement already satisfied, skipping upgrade: pytz>=2017.2 in c:\\users\\user\\anaconda3\\lib\\site-packages (from pandas) (2019.3)\n",
      "Requirement already satisfied, skipping upgrade: six>=1.5 in c:\\users\\user\\anaconda3\\lib\\site-packages (from python-dateutil>=2.6.1->pandas) (1.12.0)\n"
     ]
    },
    {
     "name": "stderr",
     "output_type": "stream",
     "text": [
      "WARNING: Retrying (Retry(total=4, connect=None, read=None, redirect=None, status=None)) after connection broken by 'NewConnectionError('<pip._vendor.urllib3.connection.VerifiedHTTPSConnection object at 0x00000165087DA6C8>: Failed to establish a new connection: [Errno 11001] getaddrinfo failed')': /simple/pandas/\n",
      "WARNING: Retrying (Retry(total=3, connect=None, read=None, redirect=None, status=None)) after connection broken by 'NewConnectionError('<pip._vendor.urllib3.connection.VerifiedHTTPSConnection object at 0x00000165087D9A48>: Failed to establish a new connection: [Errno 11001] getaddrinfo failed')': /simple/pandas/\n",
      "WARNING: Retrying (Retry(total=2, connect=None, read=None, redirect=None, status=None)) after connection broken by 'NewConnectionError('<pip._vendor.urllib3.connection.VerifiedHTTPSConnection object at 0x00000165087D9A08>: Failed to establish a new connection: [Errno 11001] getaddrinfo failed')': /simple/pandas/\n",
      "WARNING: Retrying (Retry(total=1, connect=None, read=None, redirect=None, status=None)) after connection broken by 'NewConnectionError('<pip._vendor.urllib3.connection.VerifiedHTTPSConnection object at 0x00000165087B9B48>: Failed to establish a new connection: [Errno 11001] getaddrinfo failed')': /simple/pandas/\n",
      "WARNING: Retrying (Retry(total=0, connect=None, read=None, redirect=None, status=None)) after connection broken by 'NewConnectionError('<pip._vendor.urllib3.connection.VerifiedHTTPSConnection object at 0x00000165087B9F88>: Failed to establish a new connection: [Errno 11001] getaddrinfo failed')': /simple/pandas/\n"
     ]
    }
   ],
   "source": [
    "!pip install pandas --upgrade"
   ]
  },
  {
   "cell_type": "code",
   "execution_count": 7,
   "metadata": {},
   "outputs": [],
   "source": [
    "import numpy as np\n",
    "import pandas as pd"
   ]
  },
  {
   "cell_type": "code",
   "execution_count": 9,
   "metadata": {},
   "outputs": [
    {
     "name": "stdout",
     "output_type": "stream",
     "text": [
      "Series([], dtype: float64)\n"
     ]
    }
   ],
   "source": [
    "a=pd.Series()\n",
    "print(a)"
   ]
  },
  {
   "cell_type": "code",
   "execution_count": 10,
   "metadata": {},
   "outputs": [
    {
     "data": {
      "text/plain": [
       "pandas.core.series.Series"
      ]
     },
     "execution_count": 10,
     "metadata": {},
     "output_type": "execute_result"
    }
   ],
   "source": [
    "type(a)"
   ]
  },
  {
   "cell_type": "code",
   "execution_count": 11,
   "metadata": {},
   "outputs": [
    {
     "name": "stdout",
     "output_type": "stream",
     "text": [
      "0    a\n",
      "1    b\n",
      "2    c\n",
      "3    d\n",
      "dtype: object\n"
     ]
    }
   ],
   "source": [
    "data=np.array(['a','b','c','d'])\n",
    "x=pd.Series(data)\n",
    "print(x)"
   ]
  },
  {
   "cell_type": "code",
   "execution_count": 12,
   "metadata": {},
   "outputs": [
    {
     "name": "stdout",
     "output_type": "stream",
     "text": [
      "10    a\n",
      "11    b\n",
      "12    c\n",
      "13    d\n",
      "dtype: object\n"
     ]
    }
   ],
   "source": [
    "data=np.array(['a','b','c','d'])\n",
    "x=pd.Series(data,index=[10,11,12,13])\n",
    "print(x)"
   ]
  },
  {
   "cell_type": "code",
   "execution_count": 13,
   "metadata": {},
   "outputs": [
    {
     "name": "stdout",
     "output_type": "stream",
     "text": [
      "a    1\n",
      "b    2\n",
      "c    3\n",
      "d    4\n",
      "dtype: int64\n"
     ]
    }
   ],
   "source": [
    "data={'a':1,'b':2,'c':3,'d':4}\n",
    "x=pd.Series(data)\n",
    "print(x)"
   ]
  },
  {
   "cell_type": "code",
   "execution_count": 14,
   "metadata": {},
   "outputs": [
    {
     "name": "stdout",
     "output_type": "stream",
     "text": [
      "e    NaN\n",
      "f    NaN\n",
      "b    7.0\n",
      "d    9.0\n",
      "c    8.0\n",
      "a    5.0\n",
      "dtype: float64\n"
     ]
    }
   ],
   "source": [
    "data={'a':5,'b':7,'c':8,'d':9}\n",
    "y=pd.Series(data,index={'a','e','f','c','d','b'})\n",
    "print(y)"
   ]
  },
  {
   "cell_type": "code",
   "execution_count": 16,
   "metadata": {},
   "outputs": [
    {
     "name": "stdout",
     "output_type": "stream",
     "text": [
      "1    12\n",
      "2    14\n",
      "3     5\n",
      "4     6\n",
      "dtype: int64\n"
     ]
    }
   ],
   "source": [
    "x=[12,14,5,6]\n",
    "y=pd.Series(x,index=[1,2,3,4])\n",
    "print(y)"
   ]
  },
  {
   "cell_type": "code",
   "execution_count": 17,
   "metadata": {},
   "outputs": [
    {
     "name": "stdout",
     "output_type": "stream",
     "text": [
      "0    [3, 4, 5, 6]\n",
      "1    [7, 8, 9, 2]\n",
      "dtype: object\n"
     ]
    }
   ],
   "source": [
    "x=([3,4,5,6],[7,8,9,2])\n",
    "y=pd.Series(x)\n",
    "print(y)"
   ]
  },
  {
   "cell_type": "code",
   "execution_count": 22,
   "metadata": {},
   "outputs": [
    {
     "name": "stdout",
     "output_type": "stream",
     "text": [
      "[3, 4, 5, 6]\n",
      "[7, 8, 9, 2]\n"
     ]
    }
   ],
   "source": [
    "for i in y:\n",
    "    print(i)"
   ]
  },
  {
   "cell_type": "code",
   "execution_count": null,
   "metadata": {},
   "outputs": [],
   "source": []
  },
  {
   "cell_type": "code",
   "execution_count": null,
   "metadata": {},
   "outputs": [],
   "source": []
  }
 ],
 "metadata": {
  "kernelspec": {
   "display_name": "Python 3",
   "language": "python",
   "name": "python3"
  },
  "language_info": {
   "codemirror_mode": {
    "name": "ipython",
    "version": 3
   },
   "file_extension": ".py",
   "mimetype": "text/x-python",
   "name": "python",
   "nbconvert_exporter": "python",
   "pygments_lexer": "ipython3",
   "version": "3.7.4"
  }
 },
 "nbformat": 4,
 "nbformat_minor": 2
}
